me@u20base:/mnt/d/pgw/devops$ make run
cd all-in-1 && bash all-in-1.sh -S
------- Checking input and initializing...
Management hub services will listen on http://127.0.0.1
------- Preparing IEAM template files...
Substituting environment variables into template files...
otherwise taking default values for KAFKA_USER, KAFKA_ACCESS_KEY, KAFKA_TOPIC_PREFIX, KAFKA_REP_FACTOR

------- Initializing...
------- Checking input and initializing...
Hub services will listen on https://0.0.0.0
Skipping apt-get update
Authorization in app-resource-mgr, network-resource-mgr, event-resource-mgr, gw-control, app-discovery-service, infrastrucutre-discovery-service, gw-deploy and metric-enricher service disabled
Using MOCK provider for mcnm-auth
Read more about it in https://github.ibm.com/MCNM/mcnm-auth#mock
------- Stopping Horizon services...
rm: cannot remove 'node.policy.json': No such file or directory
Cannot connect to the Docker daemon at unix:///var/run/docker.sock. Is the docker daemon running?
rm: cannot remove 'horizon': No such file or directory
------- Stopping MCNM hub services...
WARNING: The MCNM_AUTH_APPLICATION_ENDPOINT variable is not set. Defaulting to a blank string.
WARNING: The MCNM_AUTH_APPLICATION_ID variable is not set. Defaulting to a blank string.
WARNING: The AUTHRES_HUBADMIN_TENANT_ID variable is not set. Defaulting to a blank string.
WARNING: The AUTHRES_HUBADMIN_USER_ID variable is not set. Defaulting to a blank string.
WARNING: The INSTANA_CONFIG_AGENT_KEY variable is not set. Defaulting to a blank string.
WARNING: The INSTANA_CONFIG_DOWNLOAD_KEY variable is not set. Defaulting to a blank string.
Traceback (most recent call last):
  File "urllib3/connectionpool.py", line 677, in urlopen
  File "urllib3/connectionpool.py", line 392, in _make_request
  File "http/client.py", line 1277, in request
  File "http/client.py", line 1323, in _send_request
  File "http/client.py", line 1272, in endheaders
  File "http/client.py", line 1032, in _send_output
  File "http/client.py", line 972, in send
  File "docker/transport/unixconn.py", line 43, in connect
FileNotFoundError: [Errno 2] No such file or directory

During handling of the above exception, another exception occurred:

Traceback (most recent call last):
  File "requests/adapters.py", line 449, in send
  File "urllib3/connectionpool.py", line 727, in urlopen
  File "urllib3/util/retry.py", line 410, in increment
  File "urllib3/packages/six.py", line 734, in reraise
  File "urllib3/connectionpool.py", line 677, in urlopen
  File "urllib3/connectionpool.py", line 392, in _make_request
  File "http/client.py", line 1277, in request
  File "http/client.py", line 1323, in _send_request
  File "http/client.py", line 1272, in endheaders
  File "http/client.py", line 1032, in _send_output
  File "http/client.py", line 972, in send
  File "docker/transport/unixconn.py", line 43, in connect
urllib3.exceptions.ProtocolError: ('Connection aborted.', FileNotFoundError(2, 'No such file or directory'))

During handling of the above exception, another exception occurred:

Traceback (most recent call last):
  File "docker/api/client.py", line 214, in _retrieve_server_version
  File "docker/api/daemon.py", line 181, in version
  File "docker/utils/decorators.py", line 46, in inner
  File "docker/api/client.py", line 237, in _get
  File "requests/sessions.py", line 543, in get
  File "requests/sessions.py", line 530, in request
  File "requests/sessions.py", line 643, in send
  File "requests/adapters.py", line 498, in send
requests.exceptions.ConnectionError: ('Connection aborted.', FileNotFoundError(2, 'No such file or directory'))

During handling of the above exception, another exception occurred:

Traceback (most recent call last):
  File "docker-compose", line 3, in <module>
  File "compose/cli/main.py", line 81, in main
  File "compose/cli/main.py", line 200, in perform_command
  File "compose/cli/command.py", line 70, in project_from_options
  File "compose/cli/command.py", line 153, in get_project
  File "compose/cli/docker_client.py", line 43, in get_client
  File "compose/cli/docker_client.py", line 170, in docker_client
  File "docker/api/client.py", line 197, in __init__
  File "docker/api/client.py", line 222, in _retrieve_server_version
docker.errors.DockerException: Error while fetching server API version: ('Connection aborted.', FileNotFoundError(2, 'No such file or directory'))
[3241] Failed to execute script docker-compose
cd all-in-1 && bash all-in-1.sh -c ../environments/overlays/develop/default
------- Checking input and initializing...
Management hub services will listen on http://127.0.0.1
------- Preparing IEAM template files...
Substituting environment variables into template files...
otherwise taking default values for KAFKA_USER, KAFKA_ACCESS_KEY, KAFKA_TOPIC_PREFIX, KAFKA_REP_FACTOR

------- Initializing...
------- Checking input and initializing...
Hub services will listen on https://0.0.0.0
Skipping apt-get update
Authorization in app-resource-mgr, network-resource-mgr, event-resource-mgr, gw-control, app-discovery-service, infrastrucutre-discovery-service, gw-deploy and metric-enricher service disabled
Using MOCK provider for mcnm-auth
Read more about it in https://github.ibm.com/MCNM/mcnm-auth#mock
jq: error: Could not open file /home/me/.docker/config.json: No such file or directory
Logging into docker-na-public.artifactory.swg-devops.com/ccs-mcnm-team-personal-docker-local as kathy@il.ibm.com ...
jq: error: Could not open file /home/me/.docker/config.json: No such file or directory
Logging into docker-na-public.artifactory.swg-devops.com/ccs-mcnm-team-develop-docker-local as kathy@il.ibm.com ...
jq: error: Could not open file /home/me/.docker/config.json: No such file or directory
Logging into docker-na-public.artifactory.swg-devops.com/ccs-mcnm-team-testing-docker-local as kathy@il.ibm.com ...
jq: error: Could not open file /home/me/.docker/config.json: No such file or directory
Logging into docker-na-public.artifactory.swg-devops.com/ccs-mcnm-team-preprod-docker-local as kathy@il.ibm.com ...
jq: error: Could not open file /home/me/.docker/config.json: No such file or directory
Logging into docker-na-public.artifactory.swg-devops.com/ccs-mcnm-team-production-docker-local as kathy@il.ibm.com ...
jq: error: Could not open file /home/me/.docker/config.json: No such file or directory
Logging into docker-na-public.artifactory.swg-devops.com/ccs-mcnm-team-cache-docker-remote as kathy@il.ibm.com ...
jq: error: Could not open file /home/me/.docker/config.json: No such file or directory
Logging into docker-na-public.artifactory.swg-devops.com/ccs-mcnm-team-gw-releases-docker-local as kathy@il.ibm.com ...
jq: error: Could not open file /home/me/.docker/config.json: No such file or directory
Logging into docker-na-public.artifactory.swg-devops.com/ccs-mcnm-team-quay-io-docker-remote as kathy@il.ibm.com ...
jq: error: Could not open file /home/me/.docker/config.json: No such file or directory
Logging into ccs-mcnm-team-gw-develop-docker-local.artifactory.swg-devops.com as kathy@il.ibm.com ...
Generating a RSA private key
......................++++
.........++++
writing new private key to '/mnt/d/pgw/devops/all-in-1/../certs/mcnmMgmtHub.key'
-----
------- Downloading/starting MCNM hub services...
Downloading hub docker images...
Starting hub containers...
WARNING: The MCNM_AUTH_APPLICATION_ENDPOINT variable is not set. Defaulting to a blank string.
WARNING: The MCNM_AUTH_APPLICATION_ID variable is not set. Defaulting to a blank string.
WARNING: The AUTHRES_HUBADMIN_TENANT_ID variable is not set. Defaulting to a blank string.
WARNING: The AUTHRES_HUBADMIN_USER_ID variable is not set. Defaulting to a blank string.
WARNING: The INSTANA_CONFIG_AGENT_KEY variable is not set. Defaulting to a blank string.
WARNING: The INSTANA_CONFIG_DOWNLOAD_KEY variable is not set. Defaulting to a blank string.
Traceback (most recent call last):
  File "urllib3/connectionpool.py", line 677, in urlopen
  File "urllib3/connectionpool.py", line 392, in _make_request
  File "http/client.py", line 1277, in request
  File "http/client.py", line 1323, in _send_request
  File "http/client.py", line 1272, in endheaders
  File "http/client.py", line 1032, in _send_output
  File "http/client.py", line 972, in send
  File "docker/transport/unixconn.py", line 43, in connect
FileNotFoundError: [Errno 2] No such file or directory

During handling of the above exception, another exception occurred:

Traceback (most recent call last):
  File "requests/adapters.py", line 449, in send
  File "urllib3/connectionpool.py", line 727, in urlopen
  File "urllib3/util/retry.py", line 410, in increment
  File "urllib3/packages/six.py", line 734, in reraise
  File "urllib3/connectionpool.py", line 677, in urlopen
  File "urllib3/connectionpool.py", line 392, in _make_request
  File "http/client.py", line 1277, in request
  File "http/client.py", line 1323, in _send_request
  File "http/client.py", line 1272, in endheaders
  File "http/client.py", line 1032, in _send_output
  File "http/client.py", line 972, in send
  File "docker/transport/unixconn.py", line 43, in connect
urllib3.exceptions.ProtocolError: ('Connection aborted.', FileNotFoundError(2, 'No such file or directory'))

During handling of the above exception, another exception occurred:

Traceback (most recent call last):
  File "docker/api/client.py", line 214, in _retrieve_server_version
  File "docker/api/daemon.py", line 181, in version
  File "docker/utils/decorators.py", line 46, in inner
  File "docker/api/client.py", line 237, in _get
  File "requests/sessions.py", line 543, in get
  File "requests/sessions.py", line 530, in request
  File "requests/sessions.py", line 643, in send
  File "requests/adapters.py", line 498, in send
requests.exceptions.ConnectionError: ('Connection aborted.', FileNotFoundError(2, 'No such file or directory'))

During handling of the above exception, another exception occurred:

Traceback (most recent call last):
  File "docker-compose", line 3, in <module>
  File "compose/cli/main.py", line 81, in main
  File "compose/cli/main.py", line 200, in perform_command
  File "compose/cli/command.py", line 70, in project_from_options
  File "compose/cli/command.py", line 153, in get_project
  File "compose/cli/docker_client.py", line 43, in get_client
  File "compose/cli/docker_client.py", line 170, in docker_client
  File "docker/api/client.py", line 197, in __init__
  File "docker/api/client.py", line 222, in _retrieve_server_version
docker.errors.DockerException: Error while fetching server API version: ('Connection aborted.', FileNotFoundError(2, 'No such file or directory'))
[3782] Failed to execute script docker-compose
WARNING: The MCNM_AUTH_APPLICATION_ENDPOINT variable is not set. Defaulting to a blank string.
WARNING: The MCNM_AUTH_APPLICATION_ID variable is not set. Defaulting to a blank string.
WARNING: The AUTHRES_HUBADMIN_TENANT_ID variable is not set. Defaulting to a blank string.
WARNING: The AUTHRES_HUBADMIN_USER_ID variable is not set. Defaulting to a blank string.
WARNING: The INSTANA_CONFIG_AGENT_KEY variable is not set. Defaulting to a blank string.
WARNING: The INSTANA_CONFIG_DOWNLOAD_KEY variable is not set. Defaulting to a blank string.
Traceback (most recent call last):
  File "urllib3/connectionpool.py", line 677, in urlopen
  File "urllib3/connectionpool.py", line 392, in _make_request
  File "http/client.py", line 1277, in request
  File "http/client.py", line 1323, in _send_request
  File "http/client.py", line 1272, in endheaders
  File "http/client.py", line 1032, in _send_output
  File "http/client.py", line 972, in send
  File "docker/transport/unixconn.py", line 43, in connect
FileNotFoundError: [Errno 2] No such file or directory

During handling of the above exception, another exception occurred:

Traceback (most recent call last):
  File "requests/adapters.py", line 449, in send
  File "urllib3/connectionpool.py", line 727, in urlopen
  File "urllib3/util/retry.py", line 410, in increment
  File "urllib3/packages/six.py", line 734, in reraise
  File "urllib3/connectionpool.py", line 677, in urlopen
  File "urllib3/connectionpool.py", line 392, in _make_request
  File "http/client.py", line 1277, in request
  File "http/client.py", line 1323, in _send_request
  File "http/client.py", line 1272, in endheaders
  File "http/client.py", line 1032, in _send_output
  File "http/client.py", line 972, in send
  File "docker/transport/unixconn.py", line 43, in connect
urllib3.exceptions.ProtocolError: ('Connection aborted.', FileNotFoundError(2, 'No such file or directory'))

During handling of the above exception, another exception occurred:

Traceback (most recent call last):
  File "docker/api/client.py", line 214, in _retrieve_server_version
  File "docker/api/daemon.py", line 181, in version
  File "docker/utils/decorators.py", line 46, in inner
  File "docker/api/client.py", line 237, in _get
  File "requests/sessions.py", line 543, in get
  File "requests/sessions.py", line 530, in request
  File "requests/sessions.py", line 643, in send
  File "requests/adapters.py", line 498, in send
requests.exceptions.ConnectionError: ('Connection aborted.', FileNotFoundError(2, 'No such file or directory'))

During handling of the above exception, another exception occurred:

Traceback (most recent call last):
  File "docker-compose", line 3, in <module>
  File "compose/cli/main.py", line 81, in main
  File "compose/cli/main.py", line 200, in perform_command
  File "compose/cli/command.py", line 70, in project_from_options
  File "compose/cli/command.py", line 153, in get_project
  File "compose/cli/docker_client.py", line 43, in get_client
  File "compose/cli/docker_client.py", line 170, in docker_client
  File "docker/api/client.py", line 197, in __init__
  File "docker/api/client.py", line 222, in _retrieve_server_version
docker.errors.DockerException: Error while fetching server API version: ('Connection aborted.', FileNotFoundError(2, 'No such file or directory'))
[3787] Failed to execute script docker-compose
Error: exit code 255 from: starting sudo -E docker-compose services
make: *** [Makefile:17: run_develop] Error 255





me@u20base:/mnt/d/pgw/devops$ export COMPOSE_PROFILES=complete
me@u20base:/mnt/d/pgw/devops$ make run
cd all-in-1 && bash all-in-1.sh -S
otherwise taking default values for KAFKA_USER, KAFKA_ACCESS_KEY, KAFKA_TOPIC_PREFIX, KAFKA_REP_FACTOR

------- Initializing...
------- Checking input and initializing...
Hub services will listen on https://0.0.0.0
Skipping apt-get update
Authorization in app-resource-mgr, network-resource-mgr, event-resource-mgr, gw-control, app-discovery-service, infrastrucutre-discovery-service, gw-deploy and metric-enricher service disabled
Using MOCK provider for mcnm-auth
Read more about it in https://github.ibm.com/MCNM/mcnm-auth#mock
------- Stopping MCNM hub services...
WARNING: The MCNM_AUTH_APPLICATION_ENDPOINT variable is not set. Defaulting to a blank string.
WARNING: The MCNM_AUTH_APPLICATION_ID variable is not set. Defaulting to a blank string.
WARNING: The AUTHRES_HUBADMIN_TENANT_ID variable is not set. Defaulting to a blank string.
WARNING: The AUTHRES_HUBADMIN_USER_ID variable is not set. Defaulting to a blank string.
WARNING: The INSTANA_CONFIG_AGENT_KEY variable is not set. Defaulting to a blank string.
WARNING: The INSTANA_CONFIG_DOWNLOAD_KEY variable is not set. Defaulting to a blank string.
Traceback (most recent call last):
  File "urllib3/connectionpool.py", line 677, in urlopen
  File "urllib3/connectionpool.py", line 392, in _make_request
  File "http/client.py", line 1277, in request
  File "http/client.py", line 1323, in _send_request
  File "http/client.py", line 1272, in endheaders
  File "http/client.py", line 1032, in _send_output
  File "http/client.py", line 972, in send
  File "docker/transport/unixconn.py", line 43, in connect
FileNotFoundError: [Errno 2] No such file or directory

During handling of the above exception, another exception occurred:

Traceback (most recent call last):
  File "requests/adapters.py", line 449, in send
  File "urllib3/connectionpool.py", line 727, in urlopen
  File "urllib3/util/retry.py", line 410, in increment
  File "urllib3/packages/six.py", line 734, in reraise
  File "urllib3/connectionpool.py", line 677, in urlopen
  File "urllib3/connectionpool.py", line 392, in _make_request
  File "http/client.py", line 1277, in request
  File "http/client.py", line 1323, in _send_request
  File "http/client.py", line 1272, in endheaders
  File "http/client.py", line 1032, in _send_output
  File "http/client.py", line 972, in send
  File "docker/transport/unixconn.py", line 43, in connect
urllib3.exceptions.ProtocolError: ('Connection aborted.', FileNotFoundError(2, 'No such file or directory'))

During handling of the above exception, another exception occurred:

Traceback (most recent call last):
  File "docker/api/client.py", line 214, in _retrieve_server_version
  File "docker/api/daemon.py", line 181, in version
  File "docker/utils/decorators.py", line 46, in inner
  File "docker/api/client.py", line 237, in _get
  File "requests/sessions.py", line 543, in get
  File "requests/sessions.py", line 530, in request
  File "requests/sessions.py", line 643, in send
  File "requests/adapters.py", line 498, in send
requests.exceptions.ConnectionError: ('Connection aborted.', FileNotFoundError(2, 'No such file or directory'))

During handling of the above exception, another exception occurred:

Traceback (most recent call last):
  File "docker-compose", line 3, in <module>
  File "compose/cli/main.py", line 81, in main
  File "compose/cli/main.py", line 200, in perform_command
  File "compose/cli/command.py", line 70, in project_from_options
  File "compose/cli/command.py", line 153, in get_project
  File "compose/cli/docker_client.py", line 43, in get_client
  File "compose/cli/docker_client.py", line 170, in docker_client
  File "docker/api/client.py", line 197, in __init__
  File "docker/api/client.py", line 222, in _retrieve_server_version
docker.errors.DockerException: Error while fetching server API version: ('Connection aborted.', FileNotFoundError(2, 'No such file or directory'))
[4012] Failed to execute script docker-compose
cd all-in-1 && bash all-in-1.sh -c ../environments/overlays/develop/default
otherwise taking default values for KAFKA_USER, KAFKA_ACCESS_KEY, KAFKA_TOPIC_PREFIX, KAFKA_REP_FACTOR

------- Initializing...
------- Checking input and initializing...
Hub services will listen on https://0.0.0.0
Skipping apt-get update
Authorization in app-resource-mgr, network-resource-mgr, event-resource-mgr, gw-control, app-discovery-service, infrastrucutre-discovery-service, gw-deploy and metric-enricher service disabled
Using MOCK provider for mcnm-auth
Read more about it in https://github.ibm.com/MCNM/mcnm-auth#mock
jq: error: Could not open file /home/me/.docker/config.json: No such file or directory
Logging into docker-na-public.artifactory.swg-devops.com/ccs-mcnm-team-personal-docker-local as kathy@il.ibm.com ...
jq: error: Could not open file /home/me/.docker/config.json: No such file or directory
Logging into docker-na-public.artifactory.swg-devops.com/ccs-mcnm-team-develop-docker-local as kathy@il.ibm.com ...
jq: error: Could not open file /home/me/.docker/config.json: No such file or directory
Logging into docker-na-public.artifactory.swg-devops.com/ccs-mcnm-team-testing-docker-local as kathy@il.ibm.com ...
jq: error: Could not open file /home/me/.docker/config.json: No such file or directory
Logging into docker-na-public.artifactory.swg-devops.com/ccs-mcnm-team-preprod-docker-local as kathy@il.ibm.com ...
jq: error: Could not open file /home/me/.docker/config.json: No such file or directory
Logging into docker-na-public.artifactory.swg-devops.com/ccs-mcnm-team-production-docker-local as kathy@il.ibm.com ...
jq: error: Could not open file /home/me/.docker/config.json: No such file or directory
Logging into docker-na-public.artifactory.swg-devops.com/ccs-mcnm-team-cache-docker-remote as kathy@il.ibm.com ...
jq: error: Could not open file /home/me/.docker/config.json: No such file or directory
Logging into docker-na-public.artifactory.swg-devops.com/ccs-mcnm-team-gw-releases-docker-local as kathy@il.ibm.com ...
jq: error: Could not open file /home/me/.docker/config.json: No such file or directory
Logging into docker-na-public.artifactory.swg-devops.com/ccs-mcnm-team-quay-io-docker-remote as kathy@il.ibm.com ...
jq: error: Could not open file /home/me/.docker/config.json: No such file or directory
Logging into ccs-mcnm-team-gw-develop-docker-local.artifactory.swg-devops.com as kathy@il.ibm.com ...
Certificate /mnt/d/pgw/devops/all-in-1/../certs/mcnmMgmtHub.crt already exists, so not recreating it
------- Downloading/starting MCNM hub services...
Downloading hub docker images...
Starting hub containers...
WARNING: The MCNM_AUTH_APPLICATION_ENDPOINT variable is not set. Defaulting to a blank string.
WARNING: The MCNM_AUTH_APPLICATION_ID variable is not set. Defaulting to a blank string.
WARNING: The AUTHRES_HUBADMIN_TENANT_ID variable is not set. Defaulting to a blank string.
WARNING: The AUTHRES_HUBADMIN_USER_ID variable is not set. Defaulting to a blank string.
WARNING: The INSTANA_CONFIG_AGENT_KEY variable is not set. Defaulting to a blank string.
WARNING: The INSTANA_CONFIG_DOWNLOAD_KEY variable is not set. Defaulting to a blank string.
Traceback (most recent call last):
  File "urllib3/connectionpool.py", line 677, in urlopen
  File "urllib3/connectionpool.py", line 392, in _make_request
  File "http/client.py", line 1277, in request
  File "http/client.py", line 1323, in _send_request
  File "http/client.py", line 1272, in endheaders
  File "http/client.py", line 1032, in _send_output
  File "http/client.py", line 972, in send
  File "docker/transport/unixconn.py", line 43, in connect
FileNotFoundError: [Errno 2] No such file or directory

During handling of the above exception, another exception occurred:

Traceback (most recent call last):
  File "requests/adapters.py", line 449, in send
  File "urllib3/connectionpool.py", line 727, in urlopen
  File "urllib3/util/retry.py", line 410, in increment
  File "urllib3/packages/six.py", line 734, in reraise
  File "urllib3/connectionpool.py", line 677, in urlopen
  File "urllib3/connectionpool.py", line 392, in _make_request
  File "http/client.py", line 1277, in request
  File "http/client.py", line 1323, in _send_request
  File "http/client.py", line 1272, in endheaders
  File "http/client.py", line 1032, in _send_output
  File "http/client.py", line 972, in send
  File "docker/transport/unixconn.py", line 43, in connect
urllib3.exceptions.ProtocolError: ('Connection aborted.', FileNotFoundError(2, 'No such file or directory'))

During handling of the above exception, another exception occurred:

Traceback (most recent call last):
  File "docker/api/client.py", line 214, in _retrieve_server_version
  File "docker/api/daemon.py", line 181, in version
  File "docker/utils/decorators.py", line 46, in inner
  File "docker/api/client.py", line 237, in _get
  File "requests/sessions.py", line 543, in get
  File "requests/sessions.py", line 530, in request
  File "requests/sessions.py", line 643, in send
  File "requests/adapters.py", line 498, in send
requests.exceptions.ConnectionError: ('Connection aborted.', FileNotFoundError(2, 'No such file or directory'))

During handling of the above exception, another exception occurred:

Traceback (most recent call last):
  File "docker-compose", line 3, in <module>
  File "compose/cli/main.py", line 81, in main
  File "compose/cli/main.py", line 200, in perform_command
  File "compose/cli/command.py", line 70, in project_from_options
  File "compose/cli/command.py", line 153, in get_project
  File "compose/cli/docker_client.py", line 43, in get_client
  File "compose/cli/docker_client.py", line 170, in docker_client
  File "docker/api/client.py", line 197, in __init__
  File "docker/api/client.py", line 222, in _retrieve_server_version
docker.errors.DockerException: Error while fetching server API version: ('Connection aborted.', FileNotFoundError(2, 'No such file or directory'))
[4510] Failed to execute script docker-compose
WARNING: The MCNM_AUTH_APPLICATION_ENDPOINT variable is not set. Defaulting to a blank string.
WARNING: The MCNM_AUTH_APPLICATION_ID variable is not set. Defaulting to a blank string.
WARNING: The AUTHRES_HUBADMIN_TENANT_ID variable is not set. Defaulting to a blank string.
WARNING: The AUTHRES_HUBADMIN_USER_ID variable is not set. Defaulting to a blank string.
WARNING: The INSTANA_CONFIG_AGENT_KEY variable is not set. Defaulting to a blank string.
WARNING: The INSTANA_CONFIG_DOWNLOAD_KEY variable is not set. Defaulting to a blank string.
Traceback (most recent call last):
  File "urllib3/connectionpool.py", line 677, in urlopen
  File "urllib3/connectionpool.py", line 392, in _make_request
  File "http/client.py", line 1277, in request
  File "http/client.py", line 1323, in _send_request
  File "http/client.py", line 1272, in endheaders
  File "http/client.py", line 1032, in _send_output
  File "http/client.py", line 972, in send
  File "docker/transport/unixconn.py", line 43, in connect
FileNotFoundError: [Errno 2] No such file or directory

During handling of the above exception, another exception occurred:

Traceback (most recent call last):
  File "requests/adapters.py", line 449, in send
  File "urllib3/connectionpool.py", line 727, in urlopen
  File "urllib3/util/retry.py", line 410, in increment
  File "urllib3/packages/six.py", line 734, in reraise
  File "urllib3/connectionpool.py", line 677, in urlopen
  File "urllib3/connectionpool.py", line 392, in _make_request
  File "http/client.py", line 1277, in request
  File "http/client.py", line 1323, in _send_request
  File "http/client.py", line 1272, in endheaders
  File "http/client.py", line 1032, in _send_output
  File "http/client.py", line 972, in send
  File "docker/transport/unixconn.py", line 43, in connect
urllib3.exceptions.ProtocolError: ('Connection aborted.', FileNotFoundError(2, 'No such file or directory'))

During handling of the above exception, another exception occurred:

Traceback (most recent call last):
  File "docker/api/client.py", line 214, in _retrieve_server_version
  File "docker/api/daemon.py", line 181, in version
  File "docker/utils/decorators.py", line 46, in inner
  File "docker/api/client.py", line 237, in _get
  File "requests/sessions.py", line 543, in get
  File "requests/sessions.py", line 530, in request
  File "requests/sessions.py", line 643, in send
  File "requests/adapters.py", line 498, in send
requests.exceptions.ConnectionError: ('Connection aborted.', FileNotFoundError(2, 'No such file or directory'))

During handling of the above exception, another exception occurred:

Traceback (most recent call last):
  File "docker-compose", line 3, in <module>
  File "compose/cli/main.py", line 81, in main
  File "compose/cli/main.py", line 200, in perform_command
  File "compose/cli/command.py", line 70, in project_from_options
  File "compose/cli/command.py", line 153, in get_project
  File "compose/cli/docker_client.py", line 43, in get_client
  File "compose/cli/docker_client.py", line 170, in docker_client
  File "docker/api/client.py", line 197, in __init__
  File "docker/api/client.py", line 222, in _retrieve_server_version
docker.errors.DockerException: Error while fetching server API version: ('Connection aborted.', FileNotFoundError(2, 'No such file or directory'))
[4515] Failed to execute script docker-compose
Error: exit code 255 from: starting sudo -E docker-compose services
make: *** [Makefile:17: run_develop] Error 255
me@u20base:/mnt/d/pgw/devops$